Workbook

Sheet ProjectSheet
A1: Project | B1: Lower School Concept Design | C1: PROGRAMMING DOCUMENT
A2: Client | B2: Shorecrest Prep | C2: Revisions to the previous program highlighted in grey.
A3: Date | B3: 46113
A4: Revision | B4: 2
A5: Proj No | B5: 27520
A7: Dept No | B7: Program Element | C7: Room Qty/ Units | D7: Net SF/ Units | E7: Total Program SF | F7: Design Capacity / Student Stations | G7: Total Stations | H7: Notes/Comments | I7: School Questions
A8: 1 | B8: Core Curricula - Classrooms | H8: (20) existing classrooms (excluding specials) | I8: consider cubbies.
A9: 1.1 | B9: Classroom - K | C9: 4 | D9: 850 | E9: 3400 | F9: 16 | G9: 64 | H9: Relocated from Manning, smaller size (existing ~800sf); first floor | I9: configuration more like ES?
A10: 1.1.1 | B10: Restroom | C10: 4 | D10: 50 | E10: 200 | H10: (1) per classroom
A11: 1.1.2 | B11: Vestibule | C11: 4 | D11: 50 | E11: 200 | H11: connecting classrooms/RRs
A12: 1.2 | B12: Classroom - 1 | C12: 4 | D12: 850 | E12: 3400 | F12: 16 | G12: 64 | H12: Relocated from Manning, smaller size (existing ~850sf); first floor
A13: 1.2.1 | B13: Restroom | C13: 4 | D13: 50 | E13: 200 | H13: (1) per classroom
A14: 1.2.2 | B14: Vestibule | C14: 4 | D14: 50 | E14: 200 | H14: connecting classrooms/RRs
A15: 1.3 | B15: Classroom - 2 | C15: 4 | D15: 850 | E15: 3400 | F15: 16 | G15: 64 | H15: Relocated from Manning, similar size
A16: 1.3.1 | B16: Restroom | C16: 4 | D16: 50 | E16: 200 | H16: (1) per classroom
A17: 1.3.2 | B17: Vestibule | C17: 4 | D17: 50 | E17: 200 | H17: connecting classrooms/RRs
A18: 1.4 | B18: Classroom - 3 | C18: 4 | D18: 850 | E18: 3400 | F18: 16 | G18: 64 | H18: Relocated from Manning, similar size
A19: 1.4.1 | B19: Restroom | C19: 4 | D19: 50 | E19: 200 | H19: (1) per classroom
A20: 1.4.2 | B20: Vestibule | C20: 4 | D20: 50 | E20: 200 | H20: connecting classrooms/RRs
A21: 1.5 | B21: Classroom - 4 | C21: 4 | D21: 850 | E21: 3400 | F21: 16 | G21: 64 | H21: Relocated from Manning, similar size
A22: 1.5.1 | B22: Restroom | C22: 4 | D22: 50 | E22: 200 | H22: (1) per classroom
A23: 1.5.2 | B23: Vestibule | C23: 4 | D23: 50 | E23: 200 | H23: connecting classrooms/RRs
C26: Total Dept Area | E26: 19000 | F26: Total Student Stations | G26: 320
A28: 2 | B28: Core Curricula - Labs | I28: LS roundtable suggested a science lab? Could this be accommodated in the commons?
A29: 2.1 | B29: Art | C29: 1 | D29: 1000 | E29: 1000 | H29: Relocated from Raymund, similar size | I29: more about a project space for exploration
A30: 2.1.1 | B30: Storage | C30: 1 | D30: 250 | E30: 250
A31: 2.1.2 | B31: Student Restroom | C31: 1 | D31: 50 | E31: 50
A32: 2.1.3 | B32: Kiln | C32: 1 | D32: 125 | E32: 125 | H32: (1) kiln for LS
C34: Total Dept Area | E34: 1425 | F34: Total Student Stations | G34: 0
A36: 3 | B36: Core- Curricula - Specials | I36: what specials do ES utilize? Would like to keep on first floor
A37: 3.1 | B37: Spanish/Language | C37: 2 | D37: 650 | E37: 1300 | H37: Relocated from Raymund/Manning, existing 500 SF is too small
A38: 3.2 | B38: Block Room | C38: 0 | D38: 500 | E38: 0 | H38: co-located in common area
A39: 3.3 | B39: Student Restroom | C39: 2 | D39: 50 | E39: 100 | H39: shared amongst specials, if adjacency allows
A40: 3.4 | B40: Life Skills | C40: 0 | D40: 500 | E40: 0 | H40: kitchen, co-located with common area; want to be able to cook with children
A41: 3.5 | B41: STEAM | C41: 1 | D41: 1100 | E41: 1100 | H41: Spark Lab; (4)th Alpha location match that SF
A42: 3.5.1 | B42: Storage | C42: 1 | D42: 150 | E42: 150
A43: 3.6 | B43: Makerspace | C43: 1 | D43: 650 | E43: 650
A44: 3.6.1 | B44: Storage | C44: 1 | D44: 150 | E44: 150
C47: Total Dept Area | E47: 3450 | F47: Total Student Stations | G47: 0
A49: 4 | B49: Noncore Curricula Instructional Support
...

Sheet ProgramInfo
A1: Dept No | B1: Program Element | C1: Room Qty/ Units | D1: Net SF/ Units | E1: Total Program SF | F1: Design Capacity / Student Stations | G1: Total Stations | H1: Notes/Comments | I1: Conn. Primary | J1: Flr | K1: Color | L1: Color RGB | M1: Shared Access | N1: Room Width Min. | O1: Aspect Ratio
A2: {=ProjectSheet!A9:H24} -> 1.1 | B2: Classroom - K | C2: 4 | D2: 850 | E2: 3400 | F2: 16 | G2: 64 | H2: Relocated from Manning, smaller size (existing ~800sf); first floor | I2: 1.2 | J2: 1 | L2: {=findcolor(K2,"rgb")} -> 255, 255, 255 | O2: 1 to 1
A3: 1.1.1 | B3: Restroom | C3: 4 | D3: 50 | E3: 200 | F3: 0 | G3: 0 | H3: (1) per classroom | I3: 1.1 | J3: 1 | L3: {=findcolor(K3,"rgb")} -> 255, 255, 255 | M3: x | N3: 5 | O3: None
A4: 1.1.2 | B4: Vestibule | C4: 4 | D4: 50 | E4: 200 | F4: 0 | G4: 0 | H4: connecting classrooms/RRs | I4: 1.1.1 | J4: 1 | L4: {=findcolor(K4,"rgb")} -> 255, 255, 255 | M4: x
A5: 1.2 | B5: Classroom - 1 | C5: 4 | D5: 850 | E5: 3400 | F5: 16 | G5: 64 | H5: Relocated from Manning, smaller size (existing ~850sf); first floor | I5: 1.3 | J5: 1 | L5: {=findcolor(K5,"rgb")} -> 255, 255, 255 | O5: 1 to 1
A6: 1.2.1 | B6: Restroom | C6: 4 | D6: 50 | E6: 200 | F6: 0 | G6: 0 | H6: (1) per classroom | I6: 1.2 | J6: 1 | L6: {=findcolor(K6,"rgb")} -> 255, 255, 255 | M6: x
A7: 1.2.2 | B7: Vestibule | C7: 4 | D7: 50 | E7: 200 | F7: 0 | G7: 0 | H7: connecting classrooms/RRs | I7: 1.2.1 | J7: 1 | L7: {=findcolor(K7,"rgb")} -> 255, 255, 255 | M7: x
A8: 1.3 | B8: Classroom - 2 | C8: 4 | D8: 850 | E8: 3400 | F8: 16 | G8: 64 | H8: Relocated from Manning, similar size | I8: 1.4 | J8: 1 | L8: {=findcolor(K8,"rgb")} -> 255, 255, 255
A9: 1.3.1 | B9: Restroom | C9: 4 | D9: 50 | E9: 200 | F9: 0 | G9: 0 | H9: (1) per classroom | I9: 1.3 | J9: 1 | L9: {=findcolor(K9,"rgb")} -> 255, 255, 255 | M9: x
A10: 1.3.2 | B10: Vestibule | C10: 4 | D10: 50 | E10: 200 | F10: 0 | G10: 0 | H10: connecting classrooms/RRs | I10: 1.3.1 | J10: 1 | L10: {=findcolor(K10,"rgb")} -> 255, 255, 255 | M10: x
A11: 1.4 | B11: Classroom - 3 | C11: 4 | D11: 850 | E11: 3400 | F11: 16 | G11: 64 | H11: Relocated from Manning, similar size | I11: 1.5 | L11: {=findcolor(K11,"rgb")} -> 255, 255, 255
A12: 1.4.1 | B12: Restroom | C12: 4 | D12: 50 | E12: 200 | F12: 0 | G12: 0 | H12: (1) per classroom | I12: 1.4 | L12: {=findcolor(K12,"rgb")} -> 255, 255, 255 | M12: x
A13: 1.4.2 | B13: Vestibule | C13: 4 | D13: 50 | E13: 200 | F13: 0 | G13: 0 | H13: connecting classrooms/RRs | I13: 1.4.1 | L13: {=findcolor(K13,"rgb")} -> 255, 255, 255 | M13: x
A14: 1.5 | B14: Classroom - 4 | C14: 4 | D14: 850 | E14: 3400 | F14: 16 | G14: 64 | H14: Relocated from Manning, similar size | I14: 1.1 | L14: {=findcolor(K14,"rgb")} -> 255, 255, 255
A15: 1.5.1 | B15: Restroom | C15: 4 | D15: 50 | E15: 200 | F15: 0 | G15: 0 | H15: (1) per classroom | I15: 1.5 | L15: {=findcolor(K15,"rgb")} -> 255, 255, 255 | M15: x
A16: 1.5.2 | B16: Vestibule | C16: 4 | D16: 50 | E16: 200 | F16: 0 | G16: 0 | H16: connecting classrooms/RRs | I16: 1.5.1 | L16: {=findcolor(K16,"rgb")} -> 255, 255, 255 | M16: x
A17: 0 | B17: 0 | C17: 0 | D17: 0 | E17: 0 | F17: 0 | G17: 0 | H17: 0 | I17: 0 | J17: 0 | L17: {=findcolor(K17,"rgb")} -> 255, 255, 255
A18: {=ProjectSheet!A29:H33} -> 2.1 | B18: Art | C18: 1 | D18: 1000 | E18: 1000 | F18: 0 | G18: 0 | H18: Relocated from Raymund, similar size | I18: 1.4 | L18: {=findcolor(K18,"rgb")} -> 255, 255, 255
A19: 2.1.1 | B19: Storage | C19: 1 | D19: 250 | E19: 250 | F19: 0 | G19: 0 | H19: 0 | I19: 2.1 | L19: {=findcolor(K19,"rgb")} -> 255, 255, 255 | M19: x
A20: 2.1.2 | B20: Student Restroom | C20: 1 | D20: 50 | E20: 50 | F20: 0 | G20: 0 | H20: 0 | I20: 2.1 | L20: {=findcolor(K20,"rgb")} -> 255, 255, 255 | M20: x
A21: 2.1.3 | B21: Kiln | C21: 1 | D21: 125 | E21: 125 | F21: 0 | G21: 0 | H21: (1) kiln for LS | I21: 2.1 | L21: {=findcolor(K21,"rgb")} -> 255, 255, 255 | M21: x
A22: 0 | B22: 0 | C22: 0 | D22: 0 | E22: 0 | F22: 0 | G22: 0 | H22: 0 | I22: 0 | L22: {=findcolor(K22,"rgb")} -> 255, 255, 255
A23: {=ProjectSheet!A37:H45} -> 3.1 | B23: Spanish/Language | C23: 2 | D23: 650 | E23: 1300 | F23: 0 | G23: 0 | H23: Relocated from Raymund/Manning, existing 500 SF is too small | I23: 1.5 | L23: {=findcolor(K23,"rgb")} -> 255, 255, 255
A24: 3.2 | B24: Block Room | C24: 0 | D24: 500 | E24: 0 | F24: 0 | G24: 0 | H24: co-located in common area | I24: 3.1 | L24: {=findcolor(K24,"rgb")} -> 255, 255, 255
A25: 3.3 | B25: Student Restroom | C25: 2 | D25: 50 | E25: 100 | F25: 0 | G25: 0 | H25: shared amongst specials, if adjacency allows | I25: 3.1 | L25: {=findcolor(K25,"rgb")} -> 255, 255, 255
A26: 3.4 | B26: Life Skills | C26: 0 | D26: 500 | E26: 0 | F26: 0 | G26: 0 | H26: kitchen, co-located with common area; want to be able to cook with children | I26: 1.3 | L26: {=findcolor(K26,"rgb")} -> 255, 255, 255
A27: 3.5 | B27: STEAM | C27: 1 | D27: 1100 | E27: 1100 | F27: 0 | G27: 0 | H27: Spark Lab; (4)th Alpha location match that SF | I27: 1.2 | L27: {=findcolor(K27,"rgb")} -> 255, 255, 255
A28: 3.5.1 | B28: Storage | C28: 1 | D28: 150 | E28: 150 | F28: 0 | G28: 0 | H28: 0 | I28: 3.5 | L28: {=findcolor(K28,"rgb")} -> 255, 255, 255 | M28: x
A29: 3.6 | B29: Makerspace | C29: 1 | D29: 650 | E29: 650 | F29: 0 | G29: 0 | H29: 0 | I29: 1.5 | L29: {=findcolor(K29,"rgb")} -> 255, 255, 255
A30: 3.6.1 | B30: Storage | C30: 1 | D30: 150 | E30: 150 | F30: 0 | G30: 0 | H30: 0 | I30: 3.6 | L30: {=findcolor(K30,"rgb")} -> 255, 255, 255 | M30: x
A31: 0 | B31: 0 | C31: 0 | D31: 0 | E31: 0 | F31: 0 | G31: 0 | H31: 0 | I31: 0 | L31: {=findcolor(K31,"rgb")} -> 255, 255, 255
A32: {=ProjectSheet!A50:H55} -> 4.1 | B32: Common Area | C32: 5 | D32: 775 | E32: 3875 | F32: 0 | G32: 0 | H32: (1) per grade level; possibly interconnected to create central atrium; Pull out wet spaces? | I32: 1.1 | L32: {=findcolor(K32,"rgb")} -> 255, 255, 255
A33: 4.2 | B33: Grade Level Storage | C33: 5 | D33: 250 | E33: 1250 | F33: 0 | G33: 0 | H33: (1) per grade level | I33: 1.2 | L33: {=findcolor(K33,"rgb")} -> 255, 255, 255
A34: 4.3 | B34: Teacher Planning/Workroom | C34: 5 | D34: 300 | E34: 1500 | F34: 0 | G34: 0 | H34: (1) per grade level; like existing Jack&Jill connection | I34: 1.3 | L34: {=findcolor(K34,"rgb")} -> 255, 255, 255
A35: 4.4 | B35: Community Collab | C35: 0 | D35: 1500 | E35: 0 | F35: 0 | G35: 0 | H35: 0 | I35: 1.4 | L35: {=findcolor(K35,"rgb")} -> 255, 255, 255
A36: 4.5 | B36: Multipurpose Room | C36: 1 | D36: 1200 | E36: 1200 | F36: 0 | G36: 0 | H36: possible operable partition to split into two classrooms if needed; may increase in size to consider the LS classroom module | I36: 4.3 | L36: {=findcolor(K36,"rgb")} -> 255, 255, 255
A37: 0 | B37: 0 | C37: 0 | D37: 0 | E37: 0 | F37: 0 | G37: 0 | H37: 0 | I37: 0 | L37: {=findcolor(K37,"rgb")} -> 255, 255, 255
A38: {=ProjectSheet!A61:H64} -> 5.1 | B38: Music | C38: 1 | D38: 1000 | E38: 1000 | F38: 0 | G38: 0 | H38: Relocated from Raymund, similar size | I38: 1.1 | L38: {=findcolor(K38,"rgb")} -> 255, 255, 255
A39: 5.1.1 | B39: Storage | C39: 1 | D39: 300 | E39: 300 | F39: 0 | G39: 0 | H39: 0 | I39: 5.1 | L39: {=findcolor(K39,"rgb")} -> 255, 255, 255 | M39: x
A40: 5.1.2 | B40: Student Restroom | C40: 1 | D40: 50 | E40: 50 | F40: 0 | G40: 0 | H40: 0 | I40: 5.1 | L40: {=findcolor(K40,"rgb")} -> 255, 255, 255 | M40: x
...

Sheet ProjectInfo
A1: Project Name | B1: =ProjectSheet!B1 -> Lower School Concept Design
A2: Project Address
A3: General Project Boundary
